Workbook

Sheet About this study
A1: Plausible but wrong: silent analytical errors in LLM-generated charts (pilot study)
A3: Aim | B3: To measure how often a chatbot turns an underspecified data question into a chart that runs and looks plausible but is analytically wrong, and to test two remedies: asking the model to state its analytical choices before writing code (prevention), and asking the model to check finished code (detection).
A4: Data | B4: Our World in Data COVID-19 dataset, final release (data to 14 August 2024): https://raw.githubusercontent.com/owid/covid-19-data/master/public/data/owid-covid-data.csv. The data file is not included; download it from this address to reproduce the analysis.
A5: Model | B5: ChatGPT, free plan, default model, with Think and Memory off; every question in a new chat. All logged runs are from 15–16 October 2026.
A6: Questions | B6: 28 questions: 25 traps (T01–T25), each built around an analytical choice the question leaves open, and 3 fully specified controls (C01–C03). The answer key (Questions sheet, columns C and E–H) was written before any model output was seen and was never shown to the model.
A8: Step 1 – Baseline | B8: Each question was sent in a new chat with the baseline prompt (Questions, column I). The returned code was run exactly as written in Jupyter, the chart saved, and the result labelled in the Run log (condition = Baseline).
A9: Step 2 – State choices | B9: Each question was sent again in a new chat with the state-choices prompt (column J), which asks the model to list and justify its analytical choices before writing code. Logged in the Run log with condition = State choices. Tests prevention.
A10: Step 3 – Check afterwards | B10: Each baseline script was sent in a new chat with the check prompt (column K), which asks whether the chart answers the question correctly and requires a 'Correct' or 'Problem:' verdict. The model was not told the code was its own. Verdicts are recorded in the Detection log. Tests detection.
A11: Step 4 – People check | B11: Eight baseline charts (all 4 silent errors and 4 valid charts, in alternating order) were shown with their questions to 5 lay readers, each answering alone and without names recorded: 'Is this chart a correct answer to the question?' Answers are in the People check sheet.
A13: Labels (Run log) | B13: Valid = makes an acceptable choice (see 'Valid chart' column). Valid - choice stated = makes a defensible choice AND says so or adds the needed caveat. Flagged analytical error = the chart uses a misleading choice, but the model's text says so or names the better measure (the warning is in the chat, not on the chart). Silent analytical error = code runs, chart looks fine, but uses a misleading choice (see 'Misleading chart' column) and nothing in the code or text flags it. Visible error = code crashes, or the chart is empty or unreadable.
A14: Implausible? | B14: Yes if a careful reader could tell something is off from the chart alone (e.g. a vaccination rate above 100%). Silent errors that are implausible are still silent errors; the column shows how many were truly invisible.
A15: Code handling | B15: Model code was run exactly as returned and never corrected; crashes were recorded as results. Where a question was re-run, the new result replaced the old one, as decided in advance. Installation instructions given separately from the script (e.g. 'pip install') were not run as code.
A16: Fairness rule | B16: Labels were assigned against the Valid and Misleading columns of the answer key, which were fixed before any run and not changed afterwards. Where an output did not fit, the closest label was used and the reasoning recorded in Notes; judgement calls are marked as such.
... A19: Key results | B19: Baseline: all code ran (100%), but 48% of trap questions produced an analytical error (16% silent, 32% flagged). State choices: silent errors fell to 0% and analytical errors to 16%, with all controls still valid. Check afterwards: the model caught 2 of 4 silent errors with the right problem, but raised false alarms on 13 of 15 valid charts (87%). People check: 5 lay readers judged silent-error charts correct 70% of the time, against 95% for valid charts. Full figures are on the Summary sheet.

Sheet Summary
A1: Measure | B1: Baseline | C1: State choices
A2: Charts logged (all questions) | B2: =COUNTIFS('Run log'!$D$3:$D$58,"Baseline",'Run log'!$G$3:$G$58,"<>") -> 28 | C2: =COUNTIFS('Run log'!$D$3:$D$58,"State choices",'Run log'!$G$3:$G$58,"<>") -> 28
A3: Ran without error | B3: =IFERROR(COUNTIFS('Run log'!$D$3:$D$58,"Baseline",'Run log'!$G$3:$G$58,"Yes")/B2,"") -> 1 | C3: =IFERROR(COUNTIFS('Run log'!$D$3:$D$58,"State choices",'Run log'!$G$3:$G$58,"Yes")/C2,"") -> 0.96428571
A4: Trap questions labelled | B4: =COUNTIFS('Run log'!$D$3:$D$58,"Baseline",'Run log'!$C$3:$C$58,"Trap*",'Run log'!$H$3:$H$58,"<>") -> 25 | C4: =COUNTIFS('Run log'!$D$3:$D$58,"State choices",'Run log'!$C$3:$C$58,"Trap*",'Run log'!$H$3:$H$58,"<>") -> 25
A5: Silent error rate (trap questions) | B5: =IFERROR(COUNTIFS('Run log'!$D$3:$D$58,"Baseline",'Run log'!$C$3:$C$58,"Trap*",'Run log'!$H$3:$H$58,"Silent analytical error")/B4,"") -> 0.16 | C5: =IFERROR(COUNTIFS('Run log'!$D$3:$D$58,"State choices",'Run log'!$C$3:$C$58,"Trap*",'Run log'!$H$3:$H$58,"Silent analytical error")/C4,"") -> 0
A6: Flagged error rate (trap questions) | B6: =IFERROR(COUNTIFS('Run log'!$D$3:$D$58,"Baseline",'Run log'!$C$3:$C$58,"Trap*",'Run log'!$H$3:$H$58,"Flagged analytical error")/B4,"") -> 0.32 | C6: =IFERROR(COUNTIFS('Run log'!$D$3:$D$58,"State choices",'Run log'!$C$3:$C$58,"Trap*",'Run log'!$H$3:$H$58,"Flagged analytical error")/C4,"") -> 0.16
A7: Any analytical error, silent or flagged (trap questions) | B7: =IFERROR(COUNTIFS('Run log'!$D$3:$D$58,"Baseline",'Run log'!$C$3:$C$58,"Trap*",'Run log'!$H$3:$H$58,"*analytical error")/B4,"") -> 0.48 | C7: =IFERROR(COUNTIFS('Run log'!$D$3:$D$58,"State choices",'Run log'!$C$3:$C$58,"Trap*",'Run log'!$H$3:$H$58,"*analytical error")/C4,"") -> 0.16
A8: Visible error rate (trap questions) | B8: =IFERROR(COUNTIFS('Run log'!$D$3:$D$58,"Baseline",'Run log'!$C$3:$C$58,"Trap*",'Run log'!$H$3:$H$58,"Visible error")/B4,"") -> 0.04 | C8: =IFERROR(COUNTIFS('Run log'!$D$3:$D$58,"State choices",'Run log'!$C$3:$C$58,"Trap*",'Run log'!$H$3:$H$58,"Visible error")/C4,"") -> 0.04
A9: Valid (incl. choice stated), trap questions | B9: =IFERROR(COUNTIFS('Run log'!$D$3:$D$58,"Baseline",'Run log'!$C$3:$C$58,"Trap*",'Run log'!$H$3:$H$58,"Valid*")/B4,"") -> 0.48 | C9: =IFERROR(COUNTIFS('Run log'!$D$3:$D$58,"State choices",'Run log'!$C$3:$C$58,"Trap*",'Run log'!$H$3:$H$58,"Valid*")/C4,"") -> 0.8
A10: Silent errors also implausible to a careful reader | B10: =IFERROR(COUNTIFS('Run log'!$D$3:$D$58,"Baseline",'Run log'!$H$3:$H$58,"Silent analytical error",'Run log'!$J$3:$J$58,"Yes")/COUNTIFS('Run log'!$D$3:$D$58,"Baseline",'Run log'!$H$3:$H$58,"Silent analytical error"),"") -> 1 | C10: =IFERROR(COUNTIFS('Run log'!$D$3:$D$58,"State choices",'Run log'!$H$3:$H$58,"Silent analytical error",'Run log'!$J$3:$J$58,"Yes")/COUNTIFS('Run log'!$D$3:$D$58,"State choices",'Run log'!$H$3:$H$58,"Silent analytical error"),"n/a (0 silent errors)") -> n/a (0 silent errors)
A11: Control questions valid | B11: =IFERROR(COUNTIFS('Run log'!$D$3:$D$58,"Baseline",'Run log'!$C$3:$C$58,"Control",'Run log'!$H$3:$H$58,"Valid*")/COUNTIFS('Run log'!$D$3:$D$58,"Baseline",'Run log'!$C$3:$C$58,"Control",'Run log'!$H$3:$H$58,"<>"),"") -> 1 | C11: =IFERROR(COUNTIFS('Run log'!$D$3:$D$58,"State choices",'Run log'!$C$3:$C$58,"Control",'Run log'!$H$3:$H$58,"Valid*")/COUNTIFS('Run log'!$D$3:$D$58,"State choices",'Run log'!$C$3:$C$58,"Control",'Run log'!$H$3:$H$58,"<>"),"") -> 1
A13: Check afterwards (Detection log)
A14: Silent errors the model flagged with the right problem | B14: =IFERROR(COUNTIFS('Detection log'!$C$3:$C$30,"Silent analytical error",'Detection log'!$D$3:$D$30,"Problem",'Detection log'!$E$3:$E$30,"Yes")/COUNTIFS('Detection log'!$C$3:$C$30,"Silent analytical error",'Detection log'!$D$3:$D$30,"<>"),"") -> 0.5
A15: Valid charts wrongly flagged (false alarms) | B15: =IFERROR(COUNTIFS('Detection log'!$C$3:$C$30,"Valid*",'Detection log'!$D$3:$D$30,"Problem")/COUNTIFS('Detection log'!$C$3:$C$30,"Valid*",'Detection log'!$D$3:$D$30,"<>"),"") -> 0.86666667
A17: People check
A18: Silent-error charts people judged correct (missed) | B18: =IFERROR(SUMIFS('People check'!$N$3:$N$10,'People check'!$B$3:$B$10,"Silent analytical error")/SUMIFS('People check'!$M$3:$M$10,'People check'!$B$3:$B$10,"Silent analytical error"),"") -> 0.7
A19: Valid charts people judged correct | B19: =IFERROR(SUMIFS('People check'!$N$3:$N$10,'People check'!$B$3:$B$10,"Valid")/SUMIFS('People check'!$M$3:$M$10,'People check'!$B$3:$B$10,"Valid"),"") -> 0.95

Sheet Questions
A1: ID | B1: Type | C1: Hidden choice | D1: Question (as a user would ask) | E1: What the question leaves open | F1: Valid chart | G1: Misleading chart | H1: What the data show | I1: Baseline prompt | J1: State-choices prompt | K1: Check prompt (baseline code inserted at the placeholder)
A2: T01 | B2: Trap | C2: Totals vs rates; regional rows | D2: Which countries were hit hardest by COVID-19 deaths? Show me the top 10. | E2: Total deaths or deaths per person; whether rows such as 'World' and income groups count as countries. | F2: Deaths per million, countries only. | G2: Total deaths (big countries dominate), or a top 10 that includes 'World', 'Europe' or income groups. | H2: Per million: Peru 6,601; Bulgaria 5,670; North Macedonia 5,422. Totals: United States 1.19m; Brazil 702k; India 534k. | I2: I have the Our World in Data COVID-19 dataset saved as a CSV file called owid-covid-data.csv. It has one row per location per date, and these columns: iso_code, continent, location, date, total_cases, new_cases, new_cases_smoothed, total_deaths, new_deaths, new_deaths_smoothed, total_cases_per_million, new_cases_per_million, new_cases_smoothed_per_million, total_deaths_per_million, new_deaths_per_million, new_deaths_smoothed_per_million, reproduction_rate, icu_patients, icu_patients_per_million, hosp_patients, hosp_patients_per_million, weekly_icu_admissions, weekly_icu_admissions_per_million, weekly_hosp_admissions, weekly_hosp_admissions_per_million, total_tests, new_tests, total_tests_per_thousand, new_tests_per_thousand, new_tests_smoothed, new_tests_smoothed_per_thousand, positive_rate, tests_per_case, tests_units, total_vaccinations, people_vaccinated, people_fully_vaccinated, total_boosters, new_vaccinations, new_vaccinations_smoothed, total_vaccinations_per_hundred, people_vaccinated_per_hundred, people_fully_vaccinated_per_hundred, total_boosters_per_hundred, new_vaccinations_smoothed_per_million, new_people_vaccinated_smoothed, new_people_vaccinated_smoothed_per_hundred, stringency_index, population_density, median_age, aged_65_older, aged_70_older, gdp_per_capita, extreme_poverty, cardiovasc_death_rate, diabetes_prevalence, female_smokers, male_smokers, handwashing_facilities, hospital_beds_per_thousand, life_expectancy, human_development_index, population, excess_mortality_cumulative_absolute, excess_mortality_cumulative, excess_mortality, excess_mortality_cumulative_per_million. Write Python code using pandas and matplotlib that loads the file and makes a chart answering this question: Which countries were hit hardest by COVID-19 deaths? Show me the top 10. | J2: I have the Our World in Data COVID-19 dataset saved as a CSV file called owid-covid-data.csv. It has one row per location per date, and these columns: iso_code, continent, location, date, total_cases, new_cases, new_cases_smoothed, total_deaths, new_deaths, new_deaths_smoothed, total_cases_per_million, new_cases_per_million, new_cases_smoothed_per_million, total_deaths_per_million, new_deaths_per_million, new_deaths_smoothed_per_million, reproduction_rate, icu_patients, icu_patients_per_million, hosp_patients, hosp_patients_per_million, weekly_icu_admissions, weekly_icu_admissions_per_million, weekly_hosp_admissions, weekly_hosp_admissions_per_million, total_tests, new_tests, total_tests_per_thousand, new_tests_per_thousand, new_tests_smoothed, new_tests_smoothed_per_thousand, positive_rate, tests_per_case, tests_units, total_vaccinations, people_vaccinated, people_fully_vaccinated, total_boosters, new_vaccinations, new_vaccinations_smoothed, total_vaccinations_per_hundred, people_vaccinated_per_hundred, people_fully_vaccinated_per_hundred, total_boosters_per_hundred, new_vaccinations_smoothed_per_million, new_people_vaccinated_smoothed, new_people_vaccinated_smoothed_per_hundred, stringency_index, population_density, median_age, aged_65_older, aged_70_older, gdp_per_capita, extreme_poverty, cardiovasc_death_rate, diabetes_prevalence, female_smokers, male_smokers, handwashing_facilities, hospital_beds_per_thousand, life_expectancy, human_development_index, population, excess_mortality_cumulative_absolute, excess_mortality_cumulative, excess_mortality, excess_mortality_cumulative_per_million. Write Python code using pandas and matplotlib that loads the file and makes a chart answering this question: Which countries were hit hardest by COVID-19 deaths? Show me the top 10. Before you write any code, list the analytical choices this question leaves open (for example: which measure to use, totals or rates, which time period, and which rows to include). Say which option you will choose for each and why, and point out anything in the dataset that could make the chart misleading. Then write the code. | K2: A user asked this question about the Our World in Data COVID-19 dataset: Which countries were hit hardest by COVID-19 deaths? Show me the top 10. Another assistant wrote the code below to answer it. Without running it, does the chart it produces answer the question correctly? If there is a problem with how the data are measured, filtered, combined or compared, name it. Start your answer with either 'Correct' or 'Problem:'. [PASTE THE BASELINE CODE HERE]
A3: T02 | B3: Trap | C3: Totals vs rates | D3: Make a chart comparing how badly COVID affected the countries of South America. | E3: Total deaths or deaths per person. | F3: Deaths (or cases) per million. | G3: Total deaths, which mostly reflects population size. | H3: Per million: Peru 6,601; Brazil 3,339; Chile 3,208. Totals make Brazil (702k) look three times worse than Peru (221k). | I3: I have the Our World in Data COVID-19 dataset saved as a CSV file called owid-covid-data.csv. It has one row per location per date, and these columns: iso_code, continent, location, date, total_cases, new_cases, new_cases_smoothed, total_deaths, new_deaths, new_deaths_smoothed, total_cases_per_million, new_cases_per_million, new_cases_smoothed_per_million, total_deaths_per_million, new_deaths_per_million, new_deaths_smoothed_per_million, reproduction_rate, icu_patients, icu_patients_per_million, hosp_patients, hosp_patients_per_million, weekly_icu_admissions, weekly_icu_admissions_per_million, weekly_hosp_admissions, weekly_hosp_admissions_per_million, total_tests, new_tests, total_tests_per_thousand, new_tests_per_thousand, new_tests_smoothed, new_tests_smoothed_per_thousand, positive_rate, tests_per_case, tests_units, total_vaccinations, people_vaccinated, people_fully_vaccinated, total_boosters, new_vaccinations, new_vaccinations_smoothed, total_vaccinations_per_hundred, people_vaccinated_per_hundred, people_fully_vaccinated_per_hundred, total_boosters_per_hundred, new_vaccinations_smoothed_per_million, new_people_vaccinated_smoothed, new_people_vaccinated_smoothed_per_hundred, stringency_index, population_density, median_age, aged_65_older, aged_70_older, gdp_per_capita, extreme_poverty, cardiovasc_death_rate, diabetes_prevalence, female_smokers, male_smokers, handwashing_facilities, hospital_beds_per_thousand, life_expectancy, human_development_index, population, excess_mortality_cumulative_absolute, excess_mortality_cumulative, excess_mortality, excess_mortality_cumulative_per_million. Write Python code using pandas and matplotlib that loads the file and makes a chart answering this question: Make a chart comparing how badly COVID affected the countries of South America. | J3: I have the Our World in Data COVID-19 dataset saved as a CSV file called owid-covid-data.csv. It has one row per location per date, and these columns: iso_code, continent, location, date, total_cases, new_cases, new_cases_smoothed, total_deaths, new_deaths, new_deaths_smoothed, total_cases_per_million, new_cases_per_million, new_cases_smoothed_per_million, total_deaths_per_million, new_deaths_per_million, new_deaths_smoothed_per_million, reproduction_rate, icu_patients, icu_patients_per_million, hosp_patients, hosp_patients_per_million, weekly_icu_admissions, weekly_icu_admissions_per_million, weekly_hosp_admissions, weekly_hosp_admissions_per_million, total_tests, new_tests, total_tests_per_thousand, new_tests_per_thousand, new_tests_smoothed, new_tests_smoothed_per_thousand, positive_rate, tests_per_case, tests_units, total_vaccinations, people_vaccinated, people_fully_vaccinated, total_boosters, new_vaccinations, new_vaccinations_smoothed, total_vaccinations_per_hundred, people_vaccinated_per_hundred, people_fully_vaccinated_per_hundred, total_boosters_per_hundred, new_vaccinations_smoothed_per_million, new_people_vaccinated_smoothed, new_people_vaccinated_smoothed_per_hundred, stringency_index, population_density, median_age, aged_65_older, aged_70_older, gdp_per_capita, extreme_poverty, cardiovasc_death_rate, diabetes_prevalence, female_smokers, male_smokers, handwashing_facilities, hospital_beds_per_thousand, life_expectancy, human_development_index, population, excess_mortality_cumulative_absolute, excess_mortality_cumulative, excess_mortality, excess_mortality_cumulative_per_million. Write Python code using pandas and matplotlib that loads the file and makes a chart answering this question: Make a chart comparing how badly COVID affected the countries of South America. Before you write any code, list the analytical choices this question leaves open (for example: which measure to use, totals or rates, which time period, and which rows to include). Say which option you will choose for each and why, and point out anything in the dataset that could make the chart misleading. Then write the code. | K3: A user asked this question about the Our World in Data COVID-19 dataset: Make a chart comparing how badly COVID affected the countries of South America. Another assistant wrote the code below to answer it. Without running it, does the chart it produces answer the question correctly? If there is a problem with how the data are measured, filtered, combined or compared, name it. Start your answer with either 'Correct' or 'Problem:'. [PASTE THE BASELINE CODE HERE]
A4: T03 | B4: Trap | C4: Totals vs rates; tiny populations | D4: Which African countries were most affected by COVID? | E4: Totals or rates; cases or deaths; how to treat very small territories. | F4: A per-person measure. Best answers note that tiny territories (Reunion, Seychelles, Saint Helena) top the per-million list and that testing varied. | G4: Total cases (South Africa first simply because it tested and has a large population). | H4: Totals: South Africa 4.07m; Morocco 1.28m; Tunisia 1.15m. Per million (population over 1m): Mauritius, Botswana, Tunisia. | I4: I have the Our World in Data COVID-19 dataset saved as a CSV file called owid-covid-data.csv. It has one row per location per date, and these columns: iso_code, continent, location, date, total_cases, new_cases, new_cases_smoothed, total_deaths, new_deaths, new_deaths_smoothed, total_cases_per_million, new_cases_per_million, new_cases_smoothed_per_million, total_deaths_per_million, new_deaths_per_million, new_deaths_smoothed_per_million, reproduction_rate, icu_patients, icu_patients_per_million, hosp_patients, hosp_patients_per_million, weekly_icu_admissions, weekly_icu_admissions_per_million, weekly_hosp_admissions, weekly_hosp_admissions_per_million, total_tests, new_tests, total_tests_per_thousand, new_tests_per_thousand, new_tests_smoothed, new_tests_smoothed_per_thousand, positive_rate, tests_per_case, tests_units, total_vaccinations, people_vaccinated, people_fully_vaccinated, total_boosters, new_vaccinations, new_vaccinations_smoothed, total_vaccinations_per_hundred, people_vaccinated_per_hundred, people_fully_vaccinated_per_hundred, total_boosters_per_hundred, new_vaccinations_smoothed_per_million, new_people_vaccinated_smoothed, new_people_vaccinated_smoothed_per_hundred, stringency_index, population_density, median_age, aged_65_older, aged_70_older, gdp_per_capita, extreme_poverty, cardiovasc_death_rate, diabetes_prevalence, female_smokers, male_smokers, handwashing_facilities, hospital_beds_per_thousand, life_expectancy, human_development_index, population, excess_mortality_cumulative_absolute, excess_mortality_cumulative, excess_mortality, excess_mortality_cumulative_per_million. Write Python code using pandas and matplotlib that loads the file and makes a chart answering this question: Which African countries were most affected by COVID? | J4: I have the Our World in Data COVID-19 dataset saved as a CSV file called owid-covid-data.csv. It has one row per location per date, and these columns: iso_code, continent, location, date, total_cases, new_cases, new_cases_smoothed, total_deaths, new_deaths, new_deaths_smoothed, total_cases_per_million, new_cases_per_million, new_cases_smoothed_per_million, total_deaths_per_million, new_deaths_per_million, new_deaths_smoothed_per_million, reproduction_rate, icu_patients, icu_patients_per_million, hosp_patients, hosp_patients_per_million, weekly_icu_admissions, weekly_icu_admissions_per_million, weekly_hosp_admissions, weekly_hosp_admissions_per_million, total_tests, new_tests, total_tests_per_thousand, new_tests_per_thousand, new_tests_smoothed, new_tests_smoothed_per_thousand, positive_rate, tests_per_case, tests_units, total_vaccinations, people_vaccinated, people_fully_vaccinated, total_boosters, new_vaccinations, new_vaccinations_smoothed, total_vaccinations_per_hundred, people_vaccinated_per_hundred, people_fully_vaccinated_per_hundred, total_boosters_per_hundred, new_vaccinations_smoothed_per_million, new_people_vaccinated_smoothed, new_people_vaccinated_smoothed_per_hundred, stringency_index, population_density, median_age, aged_65_older, aged_70_older, gdp_per_capita, extreme_poverty, cardiovasc_death_rate, diabetes_prevalence, female_smokers, male_smokers, handwashing_facilities, hospital_beds_per_thousand, life_expectancy, human_development_index, population, excess_mortality_cumulative_absolute, excess_mortality_cumulative, excess_mortality, excess_mortality_cumulative_per_million. Write Python code using pandas and matplotlib that loads the file and makes a chart answering this question: Which African countries were most affected by COVID? Before you write any code, list the analytical choices this question leaves open (for example: which measure to use, totals or rates, which time period, and which rows to include). Say which option you will choose for each and why, and point out anything in the dataset that could make the chart misleading. Then write the code. | K4: A user asked this question about the Our World in Data COVID-19 dataset: Which African countries were most affected by COVID? Another assistant wrote the code below to answer it. Without running it, does the chart it produces answer the question correctly? If there is a problem with how the data are measured, filtered, combined or compared, name it. Start your answer with either 'Correct' or 'Problem:'. [PASTE THE BASELINE CODE HERE]
A5: T04 | B5: Trap | C5: Regional rows counted as countries | D5: Show the 10 countries with the most COVID cases. | E5: Whether 'World', continents and income groups count as countries. | F5: Countries only (totals are fine here: the question asks for 'most cases'). | G5: A top 10 filled with 'World', 'High-income countries', 'Asia', 'Europe' and similar rows. | H5: Countries only: United States 103.4m; China 99.4m; India 45.0m; France 39.0m; Germany 38.4m. With aggregate rows included, only the US and China make the top 10. | I5: I have the Our World in Data COVID-19 dataset saved as a CSV file called owid-covid-data.csv. It has one row per location per date, and these columns: iso_code, continent, location, date, total_cases, new_cases, new_cases_smoothed, total_deaths, new_deaths, new_deaths_smoothed, total_cases_per_million, new_cases_per_million, new_cases_smoothed_per_million, total_deaths_per_million, new_deaths_per_million, new_deaths_smoothed_per_million, reproduction_rate, icu_patients, icu_patients_per_million, hosp_patients, hosp_patients_per_million, weekly_icu_admissions, weekly_icu_admissions_per_million, weekly_hosp_admissions, weekly_hosp_admissions_per_million, total_tests, new_tests, total_tests_per_thousand, new_tests_per_thousand, new_tests_smoothed, new_tests_smoothed_per_thousand, positive_rate, tests_per_case, tests_units, total_vaccinations, people_vaccinated, people_fully_vaccinated, total_boosters, new_vaccinations, new_vaccinations_smoothed, total_vaccinations_per_hundred, people_vaccinated_per_hundred, people_fully_vaccinated_per_hundred, total_boosters_per_hundred, new_vaccinations_smoothed_per_million, new_people_vaccinated_smoothed, new_people_vaccinated_smoothed_per_hundred, stringency_index, population_density, median_age, aged_65_older, aged_70_older, gdp_per_capita, extreme_poverty, cardiovasc_death_rate, diabetes_prevalence, female_smokers, male_smokers, handwashing_facilities, hospital_beds_per_thousand, life_expectancy, human_development_index, population, excess_mortality_cumulative_absolute, excess_mortality_cumulative, excess_mortality, excess_mortality_cumulative_per_million. Write Python code using pandas and matplotlib that loads the file and makes a chart answering this question: Show the 10 countries with the most COVID cases. | J5: I have the Our World in Data COVID-19 dataset saved as a CSV file called owid-covid-data.csv. It has one row per location per date, and these columns: iso_code, continent, location, date, total_cases, new_cases, new_cases_smoothed, total_deaths, new_deaths, new_deaths_smoothed, total_cases_per_million, new_cases_per_million, new_cases_smoothed_per_million, total_deaths_per_million, new_deaths_per_million, new_deaths_smoothed_per_million, reproduction_rate, icu_patients, icu_patients_per_million, hosp_patients, hosp_patients_per_million, weekly_icu_admissions, weekly_icu_admissions_per_million, weekly_hosp_admissions, weekly_hosp_admissions_per_million, total_tests, new_tests, total_tests_per_thousand, new_tests_per_thousand, new_tests_smoothed, new_tests_smoothed_per_thousand, positive_rate, tests_per_case, tests_units, total_vaccinations, people_vaccinated, people_fully_vaccinated, total_boosters, new_vaccinations, new_vaccinations_smoothed, total_vaccinations_per_hundred, people_vaccinated_per_hundred, people_fully_vaccinated_per_hundred, total_boosters_per_hundred, new_vaccinations_smoothed_per_million, new_people_vaccinated_smoothed, new_people_vaccinated_smoothed_per_hundred, stringency_index, population_density, median_age, aged_65_older, aged_70_older, gdp_per_capita, extreme_poverty, cardiovasc_death_rate, diabetes_prevalence, female_smokers, male_smokers, handwashing_facilities, hospital_beds_per_thousand, life_expectancy, human_development_index, population, excess_mortality_cumulative_absolute, excess_mortality_cumulative, excess_mortality, excess_mortality_cumulative_per_million. Write Python code using pandas and matplotlib that loads the file and makes a chart answering this question: Show the 10 countries with the most COVID cases. Before you write any code, list the analytical choices this question leaves open (for example: which measure to use, totals or rates, which time period, and which rows to include). Say which option you will choose for each and why, and point out anything in the dataset that could make the chart misleading. Then write the code. | K5: A user asked this question about the Our World in Data COVID-19 dataset: Show the 10 countries with the most COVID cases. Another assistant wrote the code below to answer it. Without running it, does the chart it produces answer the question correctly? If there is a problem with how the data are measured, filtered, combined or compared, name it. Start your answer with either 'Correct' or 'Problem:'. [PASTE THE BASELINE CODE HERE]
A6: T05 | B6: Trap | C6: Summing a running total; double counting | D6: How many people died of COVID in each continent? Show it as a bar chart. | E6: How to total a cumulative column; whether to add countries or use the continent rows. | F6: Latest cumulative deaths per country summed by continent (or the continent rows themselves). | G6: Summing the cumulative column across all dates (gives billions of deaths), or adding aggregate rows on top of countries. | H6: Europe 2.10m; North America 1.67m; Asia 1.64m; South America 1.35m; Africa 259k; Oceania 33k (world 7.06m). Summing every date gives about 8 billion. | I6: I have the Our World in Data COVID-19 dataset saved as a CSV file called owid-covid-data.csv. It has one row per location per date, and these columns: iso_code, continent, location, date, total_cases, new_cases, new_cases_smoothed, total_deaths, new_deaths, new_deaths_smoothed, total_cases_per_million, new_cases_per_million, new_cases_smoothed_per_million, total_deaths_per_million, new_deaths_per_million, new_deaths_smoothed_per_million, reproduction_rate, icu_patients, icu_patients_per_million, hosp_patients, hosp_patients_per_million, weekly_icu_admissions, weekly_icu_admissions_per_million, weekly_hosp_admissions, weekly_hosp_admissions_per_million, total_tests, new_tests, total_tests_per_thousand, new_tests_per_thousand, new_tests_smoothed, new_tests_smoothed_per_thousand, positive_rate, tests_per_case, tests_units, total_vaccinations, people_vaccinated, people_fully_vaccinated, total_boosters, new_vaccinations, new_vaccinations_smoothed, total_vaccinations_per_hundred, people_vaccinated_per_hundred, people_fully_vaccinated_per_hundred, total_boosters_per_hundred, new_vaccinations_smoothed_per_million, new_people_vaccinated_smoothed, new_people_vaccinated_smoothed_per_hundred, stringency_index, population_density, median_age, aged_65_older, aged_70_older, gdp_per_capita, extreme_poverty, cardiovasc_death_rate, diabetes_prevalence, female_smokers, male_smokers, handwashing_facilities, hospital_beds_per_thousand, life_expectancy, human_development_index, population, excess_mortality_cumulative_absolute, excess_mortality_cumulative, excess_mortality, excess_mortality_cumulative_per_million. Write Python code using pandas and matplotlib that loads the file and makes a chart answering this question: How many people died of COVID in each continent? Show it as a bar chart. | J6: I have the Our World in Data COVID-19 dataset saved as a CSV file called owid-covid-data.csv. It has one row per location per date, and these columns: iso_code, continent, location, date, total_cases, new_cases, new_cases_smoothed, total_deaths, new_deaths, new_deaths_smoothed, total_cases_per_million, new_cases_per_million, new_cases_smoothed_per_million, total_deaths_per_million, new_deaths_per_million, new_deaths_smoothed_per_million, reproduction_rate, icu_patients, icu_patients_per_million, hosp_patients, hosp_patients_per_million, weekly_icu_admissions, weekly_icu_admissions_per_million, weekly_hosp_admissions, weekly_hosp_admissions_per_million, total_tests, new_tests, total_tests_per_thousand, new_tests_per_thousand, new_tests_smoothed, new_tests_smoothed_per_thousand, positive_rate, tests_per_case, tests_units, total_vaccinations, people_vaccinated, people_fully_vaccinated, total_boosters, new_vaccinations, new_vaccinations_smoothed, total_vaccinations_per_hundred, people_vaccinated_per_hundred, people_fully_vaccinated_per_hundred, total_boosters_per_hundred, new_vaccinations_smoothed_per_million, new_people_vaccinated_smoothed, new_people_vaccinated_smoothed_per_hundred, stringency_index, population_density, median_age, aged_65_older, aged_70_older, gdp_per_capita, extreme_poverty, cardiovasc_death_rate, diabetes_prevalence, female_smokers, male_smokers, handwashing_facilities, hospital_beds_per_thousand, life_expectancy, human_development_index, population, excess_mortality_cumulative_absolute, excess_mortality_cumulative, excess_mortality, excess_mortality_cumulative_per_million. Write Python code using pandas and matplotlib that loads the file and makes a chart answering this question: How many people died of COVID in each continent? Show it as a bar chart. Before you write any code, list the analytical choices this question leaves open (for example: which measure to use, totals or rates, which time period, and which rows to include). Say which option you will choose for each and why, and point out anything in the dataset that could make the chart misleading. Then write the code. | K6: A user asked this question about the Our World in Data COVID-19 dataset: How many people died of COVID in each continent? Show it as a bar chart. Another assistant wrote the code below to answer it. Without running it, does the chart it produces answer the question correctly? If there is a problem with how the data are measured, filtered, combined or compared, name it. Start your answer with either 'Correct' or 'Problem:'. [PASTE THE BASELINE CODE HERE]
A7: T06 | B7: Trap | C7: Unweighted average of countries | D7: What share of people in Africa were fully vaccinated against COVID? | E7: Share of all people (population-weighted) or the average of country percentages. | F7: Population-weighted share, i.e. the 'Africa' row: 32.4%. | G7: Simple average of country percentages: 35.4%, presented as the share of people. | H7: Weighted 32.4% vs unweighted 35.4%. | I7: I have the Our World in Data COVID-19 dataset saved as a CSV file called owid-covid-data.csv. It has one row per location per date, and these columns: iso_code, continent, location, date, total_cases, new_cases, new_cases_smoothed, total_deaths, new_deaths, new_deaths_smoothed, total_cases_per_million, new_cases_per_million, new_cases_smoothed_per_million, total_deaths_per_million, new_deaths_per_million, new_deaths_smoothed_per_million, reproduction_rate, icu_patients, icu_patients_per_million, hosp_patients, hosp_patients_per_million, weekly_icu_admissions, weekly_icu_admissions_per_million, weekly_hosp_admissions, weekly_hosp_admissions_per_million, total_tests, new_tests, total_tests_per_thousand, new_tests_per_thousand, new_tests_smoothed, new_tests_smoothed_per_thousand, positive_rate, tests_per_case, tests_units, total_vaccinations, people_vaccinated, people_fully_vaccinated, total_boosters, new_vaccinations, new_vaccinations_smoothed, total_vaccinations_per_hundred, people_vaccinated_per_hundred, people_fully_vaccinated_per_hundred, total_boosters_per_hundred, new_vaccinations_smoothed_per_million, new_people_vaccinated_smoothed, new_people_vaccinated_smoothed_per_hundred, stringency_index, population_density, median_age, aged_65_older, aged_70_older, gdp_per_capita, extreme_poverty, cardiovasc_death_rate, diabetes_prevalence, female_smokers, male_smokers, handwashing_facilities, hospital_beds_per_thousand, life_expectancy, human_development_index, population, excess_mortality_cumulative_absolute, excess_mortality_cumulative, excess_mortality, excess_mortality_cumulative_per_million. Write Python code using pandas and matplotlib that loads the file and makes a chart answering this question: What share of people in Africa were fully vaccinated against COVID? | J7: I have the Our World in Data COVID-19 dataset saved as a CSV file called owid-covid-data.csv. It has one row per location per date, and these columns: iso_code, continent, location, date, total_cases, new_cases, new_cases_smoothed, total_deaths, new_deaths, new_deaths_smoothed, total_cases_per_million, new_cases_per_million, new_cases_smoothed_per_million, total_deaths_per_million, new_deaths_per_million, new_deaths_smoothed_per_million, reproduction_rate, icu_patients, icu_patients_per_million, hosp_patients, hosp_patients_per_million, weekly_icu_admissions, weekly_icu_admissions_per_million, weekly_hosp_admissions, weekly_hosp_admissions_per_million, total_tests, new_tests, total_tests_per_thousand, new_tests_per_thousand, new_tests_smoothed, new_tests_smoothed_per_thousand, positive_rate, tests_per_case, tests_units, total_vaccinations, people_vaccinated, people_fully_vaccinated, total_boosters, new_vaccinations, new_vaccinations_smoothed, total_vaccinations_per_hundred, people_vaccinated_per_hundred, people_fully_vaccinated_per_hundred, total_boosters_per_hundred, new_vaccinations_smoothed_per_million, new_people_vaccinated_smoothed, new_people_vaccinated_smoothed_per_hundred, stringency_index, population_density, median_age, aged_65_older, aged_70_older, gdp_per_capita, extreme_poverty, cardiovasc_death_rate, diabetes_prevalence, female_smokers, male_smokers, handwashing_facilities, hospital_beds_per_thousand, life_expectancy, human_development_index, population, excess_mortality_cumulative_absolute, excess_mortality_cumulative, excess_mortality, excess_mortality_cumulative_per_million. Write Python code using pandas and matplotlib that loads the file and makes a chart answering this question: What share of people in Africa were fully vaccinated against COVID? Before you write any code, list the analytical choices this question leaves open (for example: which measure to use, totals or rates, which time period, and which rows to include). Say which option you will choose for each and why, and point out anything in the dataset that could make the chart misleading. Then write the code. | K7: A user asked this question about the Our World in Data COVID-19 dataset: What share of people in Africa were fully vaccinated against COVID? Another assistant wrote the code below to answer it. Without running it, does the chart it produces answer the question correctly? If there is a problem with how the data are measured, filtered, combined or compared, name it. Start your answer with either 'Correct' or 'Problem:'. [PASTE THE BASELINE CODE HERE]
A8: T07 | B8: Trap | C8: Running total vs yearly count | D8: Were there more COVID deaths in the United States in 2021 or in 2022? Make a chart. | E8: Deaths during each year, or the running total at the end of each year. | F8: Sum new deaths within each year: 2021 = 469,667; 2022 = 267,389, so 2021. | G8: Year-end running totals (812,587 vs 1,079,976), which wrongly suggest 2022. | H8: The trap reverses the answer. | I8: I have the Our World in Data COVID-19 dataset saved as a CSV file called owid-covid-data.csv. It has one row per location per date, and these columns: iso_code, continent, location, date, total_cases, new_cases, new_cases_smoothed, total_deaths, new_deaths, new_deaths_smoothed, total_cases_per_million, new_cases_per_million, new_cases_smoothed_per_million, total_deaths_per_million, new_deaths_per_million, new_deaths_smoothed_per_million, reproduction_rate, icu_patients, icu_patients_per_million, hosp_patients, hosp_patients_per_million, weekly_icu_admissions, weekly_icu_admissions_per_million, weekly_hosp_admissions, weekly_hosp_admissions_per_million, total_tests, new_tests, total_tests_per_thousand, new_tests_per_thousand, new_tests_smoothed, new_tests_smoothed_per_thousand, positive_rate, tests_per_case, tests_units, total_vaccinations, people_vaccinated, people_fully_vaccinated, total_boosters, new_vaccinations, new_vaccinations_smoothed, total_vaccinations_per_hundred, people_vaccinated_per_hundred, people_fully_vaccinated_per_hundred, total_boosters_per_hundred, new_vaccinations_smoothed_per_million, new_people_vaccinated_smoothed, new_people_vaccinated_smoothed_per_hundred, stringency_index, population_density, median_age, aged_65_older, aged_70_older, gdp_per_capita, extreme_poverty, cardiovasc_death_rate, diabetes_prevalence, female_smokers, male_smokers, handwashing_facilities, hospital_beds_per_thousand, life_expectancy, human_development_index, population, excess_mortality_cumulative_absolute, excess_mortality_cumulative, excess_mortality, excess_mortality_cumulative_per_million. Write Python code using pandas and matplotlib that loads the file and makes a chart answering this question: Were there more COVID deaths in the United States in 2021 or in 2022? Make a chart. | J8: I have the Our World in Data COVID-19 dataset saved as a CSV file called owid-covid-data.csv. It has one row per location per date, and these columns: iso_code, continent, location, date, total_cases, new_cases, new_cases_smoothed, total_deaths, new_deaths, new_deaths_smoothed, total_cases_per_million, new_cases_per_million, new_cases_smoothed_per_million, total_deaths_per_million, new_deaths_per_million, new_deaths_smoothed_per_million, reproduction_rate, icu_patients, icu_patients_per_million, hosp_patients, hosp_patients_per_million, weekly_icu_admissions, weekly_icu_admissions_per_million, weekly_hosp_admissions, weekly_hosp_admissions_per_million, total_tests, new_tests, total_tests_per_thousand, new_tests_per_thousand, new_tests_smoothed, new_tests_smoothed_per_thousand, positive_rate, tests_per_case, tests_units, total_vaccinations, people_vaccinated, people_fully_vaccinated, total_boosters, new_vaccinations, new_vaccinations_smoothed, total_vaccinations_per_hundred, people_vaccinated_per_hundred, people_fully_vaccinated_per_hundred, total_boosters_per_hundred, new_vaccinations_smoothed_per_million, new_people_vaccinated_smoothed, new_people_vaccinated_smoothed_per_hundred, stringency_index, population_density, median_age, aged_65_older, aged_70_older, gdp_per_capita, extreme_poverty, cardiovasc_death_rate, diabetes_prevalence, female_smokers, male_smokers, handwashing_facilities, hospital_beds_per_thousand, life_expectancy, human_development_index, population, excess_mortality_cumulative_absolute, excess_mortality_cumulative, excess_mortality, excess_mortality_cumulative_per_million. Write Python code using pandas and matplotlib that loads the file and makes a chart answering this question: Were there more COVID deaths in the United States in 2021 or in 2022? Make a chart. Before you write any code, list the analytical choices this question leaves open (for example: which measure to use, totals or rates, which time period, and which rows to include). Say which option you will choose for each and why, and point out anything in the dataset that could make the chart misleading. Then write the code. | K8: A user asked this question about the Our World in Data COVID-19 dataset: Were there more COVID deaths in the United States in 2021 or in 2022? Make a chart. Another assistant wrote the code below to answer it. Without running it, does the chart it produces answer the question correctly? If there is a problem with how the data are measured, filtered, combined or compared, name it. Start your answer with either 'Correct' or 'Problem:'. [PASTE THE BASELINE CODE HERE]
A9: T08 | B9: Trap | C9: Running total hides waves; weekly reporting | D9: Plot how COVID deaths changed over time in Italy. | E9: Running total or deaths per period; how to handle weekly reporting. | F9: Weekly deaths or the 7-day smoothed column, showing the waves. | G9: Silent: the running total (one rising line, no waves). Visible: raw daily values, which are weekly totals on Sundays and zero on every other day, giving a spiky comb. | H9: All non-zero daily deaths in this file fall on Sundays: the data are weekly. | I9: I have the Our World in Data COVID-19 dataset saved as a CSV file called owid-covid-data.csv. It has one row per location per date, and these columns: iso_code, continent, location, date, total_cases, new_cases, new_cases_smoothed, total_deaths, new_deaths, new_deaths_smoothed, total_cases_per_million, new_cases_per_million, new_cases_smoothed_per_million, total_deaths_per_million, new_deaths_per_million, new_deaths_smoothed_per_million, reproduction_rate, icu_patients, icu_patients_per_million, hosp_patients, hosp_patients_per_million, weekly_icu_admissions, weekly_icu_admissions_per_million, weekly_hosp_admissions, weekly_hosp_admissions_per_million, total_tests, new_tests, total_tests_per_thousand, new_tests_per_thousand, new_tests_smoothed, new_tests_smoothed_per_thousand, positive_rate, tests_per_case, tests_units, total_vaccinations, people_vaccinated, people_fully_vaccinated, total_boosters, new_vaccinations, new_vaccinations_smoothed, total_vaccinations_per_hundred, people_vaccinated_per_hundred, people_fully_vaccinated_per_hundred, total_boosters_per_hundred, new_vaccinations_smoothed_per_million, new_people_vaccinated_smoothed, new_people_vaccinated_smoothed_per_hundred, stringency_index, population_density, median_age, aged_65_older, aged_70_older, gdp_per_capita, extreme_poverty, cardiovasc_death_rate, diabetes_prevalence, female_smokers, male_smokers, handwashing_facilities, hospital_beds_per_thousand, life_expectancy, human_development_index, population, excess_mortality_cumulative_absolute, excess_mortality_cumulative, excess_mortality, excess_mortality_cumulative_per_million. Write Python code using pandas and matplotlib that loads the file and makes a chart answering this question: Plot how COVID deaths changed over time in Italy. | J9: I have the Our World in Data COVID-19 dataset saved as a CSV file called owid-covid-data.csv. It has one row per location per date, and these columns: iso_code, continent, location, date, total_cases, new_cases, new_cases_smoothed, total_deaths, new_deaths, new_deaths_smoothed, total_cases_per_million, new_cases_per_million, new_cases_smoothed_per_million, total_deaths_per_million, new_deaths_per_million, new_deaths_smoothed_per_million, reproduction_rate, icu_patients, icu_patients_per_million, hosp_patients, hosp_patients_per_million, weekly_icu_admissions, weekly_icu_admissions_per_million, weekly_hosp_admissions, weekly_hosp_admissions_per_million, total_tests, new_tests, total_tests_per_thousand, new_tests_per_thousand, new_tests_smoothed, new_tests_smoothed_per_thousand, positive_rate, tests_per_case, tests_units, total_vaccinations, people_vaccinated, people_fully_vaccinated, total_boosters, new_vaccinations, new_vaccinations_smoothed, total_vaccinations_per_hundred, people_vaccinated_per_hundred, people_fully_vaccinated_per_hundred, total_boosters_per_hundred, new_vaccinations_smoothed_per_million, new_people_vaccinated_smoothed, new_people_vaccinated_smoothed_per_hundred, stringency_index, population_density, median_age, aged_65_older, aged_70_older, gdp_per_capita, extreme_poverty, cardiovasc_death_rate, diabetes_prevalence, female_smokers, male_smokers, handwashing_facilities, hospital_beds_per_thousand, life_expectancy, human_development_index, population, excess_mortality_cumulative_absolute, excess_mortality_cumulative, excess_mortality, excess_mortality_cumulative_per_million. Write Python code using pandas and matplotlib that loads the file and makes a chart answering this question: Plot how COVID deaths changed over time in Italy. Before you write any code, list the analytical choices this question leaves open (for example: which measure to use, totals or rates, which time period, and which rows to include). Say which option you will choose for each and why, and point out anything in the dataset that could make the chart misleading. Then write the code. | K9: A user asked this question about the Our World in Data COVID-19 dataset: Plot how COVID deaths changed over time in Italy. Another assistant wrote the code below to answer it. Without running it, does the chart it produces answer the question correctly? If there is a problem with how the data are measured, filtered, combined or compared, name it. Start your answer with either 'Correct' or 'Problem:'. [PASTE THE BASELINE CODE HERE]
A10: T09 | B10: Trap | C10: Running total | D10: Did COVID deaths in the United Kingdom fall after vaccines were rolled out? | E10: Running total or deaths per period; when vaccination started. | F10: Weekly or smoothed new deaths over time, with the vaccine rollout (December 2020) marked or vaccination shown alongside. | G10: The running total, which can only rise and so seems to say 'no'. | H10: Deaths per week fell sharply in early 2021. | I10: I have the Our World in Data COVID-19 dataset saved as a CSV file called owid-covid-data.csv. It has one row per location per date, and these columns: iso_code, continent, location, date, total_cases, new_cases, new_cases_smoothed, total_deaths, new_deaths, new_deaths_smoothed, total_cases_per_million, new_cases_per_million, new_cases_smoothed_per_million, total_deaths_per_million, new_deaths_per_million, new_deaths_smoothed_per_million, reproduction_rate, icu_patients, icu_patients_per_million, hosp_patients, hosp_patients_per_million, weekly_icu_admissions, weekly_icu_admissions_per_million, weekly_hosp_admissions, weekly_hosp_admissions_per_million, total_tests, new_tests, total_tests_per_thousand, new_tests_per_thousand, new_tests_smoothed, new_tests_smoothed_per_thousand, positive_rate, tests_per_case, tests_units, total_vaccinations, people_vaccinated, people_fully_vaccinated, total_boosters, new_vaccinations, new_vaccinations_smoothed, total_vaccinations_per_hundred, people_vaccinated_per_hundred, people_fully_vaccinated_per_hundred, total_boosters_per_hundred, new_vaccinations_smoothed_per_million, new_people_vaccinated_smoothed, new_people_vaccinated_smoothed_per_hundred, stringency_index, population_density, median_age, aged_65_older, aged_70_older, gdp_per_capita, extreme_poverty, cardiovasc_death_rate, diabetes_prevalence, female_smokers, male_smokers, handwashing_facilities, hospital_beds_per_thousand, life_expectancy, human_development_index, population, excess_mortality_cumulative_absolute, excess_mortality_cumulative, excess_mortality, excess_mortality_cumulative_per_million. Write Python code using pandas and matplotlib that loads the file and makes a chart answering this question: Did COVID deaths in the United Kingdom fall after vaccines were rolled out? | J10: I have the Our World in Data COVID-19 dataset saved as a CSV file called owid-covid-data.csv. It has one row per location per date, and these columns: iso_code, continent, location, date, total_cases, new_cases, new_cases_smoothed, total_deaths, new_deaths, new_deaths_smoothed, total_cases_per_million, new_cases_per_million, new_cases_smoothed_per_million, total_deaths_per_million, new_deaths_per_million, new_deaths_smoothed_per_million, reproduction_rate, icu_patients, icu_patients_per_million, hosp_patients, hosp_patients_per_million, weekly_icu_admissions, weekly_icu_admissions_per_million, weekly_hosp_admissions, weekly_hosp_admissions_per_million, total_tests, new_tests, total_tests_per_thousand, new_tests_per_thousand, new_tests_smoothed, new_tests_smoothed_per_thousand, positive_rate, tests_per_case, tests_units, total_vaccinations, people_vaccinated, people_fully_vaccinated, total_boosters, new_vaccinations, new_vaccinations_smoothed, total_vaccinations_per_hundred, people_vaccinated_per_hundred, people_fully_vaccinated_per_hundred, total_boosters_per_hundred, new_vaccinations_smoothed_per_million, new_people_vaccinated_smoothed, new_people_vaccinated_smoothed_per_hundred, stringency_index, population_density, median_age, aged_65_older, aged_70_older, gdp_per_capita, extreme_poverty, cardiovasc_death_rate, diabetes_prevalence, female_smokers, male_smokers, handwashing_facilities, hospital_beds_per_thousand, life_expectancy, human_development_index, population, excess_mortality_cumulative_absolute, excess_mortality_cumulative, excess_mortality, excess_mortality_cumulative_per_million. Write Python code using pandas and matplotlib that loads the file and makes a chart answering this question: Did COVID deaths in the United Kingdom fall after vaccines were rolled out? Before you write any code, list the analytical choices this question leaves open (for example: which measure to use, totals or rates, which time period, and which rows to include). Say which option you will choose for each and why, and point out anything in the dataset that could make the chart misleading. Then write the code. | K10: A user asked this question about the Our World in Data COVID-19 dataset: Did COVID deaths in the United Kingdom fall after vaccines were rolled out? Another assistant wrote the code below to answer it. Without running it, does the chart it produces answer the question correctly? If there is a problem with how the data are measured, filtered, combined or compared, name it. Start your answer with either 'Correct' or 'Problem:'. [PASTE THE BASELINE CODE HERE]
A11: T10 | B11: Trap | C11: Weekly data read as daily | D11: On which single day did the most people die of COVID in the United States? | E11: Whether the data really are daily. | F11: Says the data are weekly totals recorded on Sundays, so a single day cannot be identified; reports the peak week instead. | G11: Names Sunday 17 January 2021 with 23,312 deaths as a single day. | H11: 23,312 is the total for the week ending 17 January 2021. | I11: I have the Our World in Data COVID-19 dataset saved as a CSV file called owid-covid-data.csv. It has one row per location per date, and these columns: iso_code, continent, location, date, total_cases, new_cases, new_cases_smoothed, total_deaths, new_deaths, new_deaths_smoothed, total_cases_per_million, new_cases_per_million, new_cases_smoothed_per_million, total_deaths_per_million, new_deaths_per_million, new_deaths_smoothed_per_million, reproduction_rate, icu_patients, icu_patients_per_million, hosp_patients, hosp_patients_per_million, weekly_icu_admissions, weekly_icu_admissions_per_million, weekly_hosp_admissions, weekly_hosp_admissions_per_million, total_tests, new_tests, total_tests_per_thousand, new_tests_per_thousand, new_tests_smoothed, new_tests_smoothed_per_thousand, positive_rate, tests_per_case, tests_units, total_vaccinations, people_vaccinated, people_fully_vaccinated, total_boosters, new_vaccinations, new_vaccinations_smoothed, total_vaccinations_per_hundred, people_vaccinated_per_hundred, people_fully_vaccinated_per_hundred, total_boosters_per_hundred, new_vaccinations_smoothed_per_million, new_people_vaccinated_smoothed, new_people_vaccinated_smoothed_per_hundred, stringency_index, population_density, median_age, aged_65_older, aged_70_older, gdp_per_capita, extreme_poverty, cardiovasc_death_rate, diabetes_prevalence, female_smokers, male_smokers, handwashing_facilities, hospital_beds_per_thousand, life_expectancy, human_development_index, population, excess_mortality_cumulative_absolute, excess_mortality_cumulative, excess_mortality, excess_mortality_cumulative_per_million. Write Python code using pandas and matplotlib that loads the file and makes a chart answering this question: On which single day did the most people die of COVID in the United States? | J11: I have the Our World in Data COVID-19 dataset saved as a CSV file called owid-covid-data.csv. It has one row per location per date, and these columns: iso_code, continent, location, date, total_cases, new_cases, new_cases_smoothed, total_deaths, new_deaths, new_deaths_smoothed, total_cases_per_million, new_cases_per_million, new_cases_smoothed_per_million, total_deaths_per_million, new_deaths_per_million, new_deaths_smoothed_per_million, reproduction_rate, icu_patients, icu_patients_per_million, hosp_patients, hosp_patients_per_million, weekly_icu_admissions, weekly_icu_admissions_per_million, weekly_hosp_admissions, weekly_hosp_admissions_per_million, total_tests, new_tests, total_tests_per_thousand, new_tests_per_thousand, new_tests_smoothed, new_tests_smoothed_per_thousand, positive_rate, tests_per_case, tests_units, total_vaccinations, people_vaccinated, people_fully_vaccinated, total_boosters, new_vaccinations, new_vaccinations_smoothed, total_vaccinations_per_hundred, people_vaccinated_per_hundred, people_fully_vaccinated_per_hundred, total_boosters_per_hundred, new_vaccinations_smoothed_per_million, new_people_vaccinated_smoothed, new_people_vaccinated_smoothed_per_hundred, stringency_index, population_density, median_age, aged_65_older, aged_70_older, gdp_per_capita, extreme_poverty, cardiovasc_death_rate, diabetes_prevalence, female_smokers, male_smokers, handwashing_facilities, hospital_beds_per_thousand, life_expectancy, human_development_index, population, excess_mortality_cumulative_absolute, excess_mortality_cumulative, excess_mortality, excess_mortality_cumulative_per_million. Write Python code using pandas and matplotlib that loads the file and makes a chart answering this question: On which single day did the most people die of COVID in the United States? Before you write any code, list the analytical choices this question leaves open (for example: which measure to use, totals or rates, which time period, and which rows to include). Say which option you will choose for each and why, and point out anything in the dataset that could make the chart misleading. Then write the code. | K11: A user asked this question about the Our World in Data COVID-19 dataset: On which single day did the most people die of COVID in the United States? Another assistant wrote the code below to answer it. Without running it, does the chart it produces answer the question correctly? If there is a problem with how the data are measured, filtered, combined or compared, name it. Start your answer with either 'Correct' or 'Problem:'. [PASTE THE BASELINE CODE HERE]
